<!--https://automaticaddison.com/set-up-lidar-for-a-simulated-mobile-robot-in-ros-2/
-->
<?xml version='1.0'?>
<sdf version='1.4'>
  <model name="osiris_exo">
    <static>false</static>

      <pose>0.0 0.0 0.0 0.0 0.0 0.0</pose>
      <link name="base_footprint"/>

      <link name="base_link">
        <pose>0 0 0.1 0 0 0</pose>

        <inertial>
          <inertia>
            <ixx>0.566666667</ixx>
            <ixy>0.000</ixy>
            <ixz>0.000</ixz>
            <iyy>0.666666667</iyy>
            <iyz>0.000</iyz>
            <izz>0.166666667</izz>
          </inertia>
          <mass>40.0</mass>
        </inertial>

        <collision name="collision">
          <geometry>
            <box> 
              <size>0.4 0.2 0.1</size>
            </box>
          </geometry>
        </collision>
        <visual name="visual">
          <geometry>
            <box> 
              <size>0.4 0.2 0.1</size>
            </box>
          </geometry>
        </visual>
      </link>

      <link name="left_front_wheel">
        <pose>0.15 0.13 0.1 0 1.5707 1.5707</pose>

        <inertial>
          <inertia>
            <ixx>0.016145833</ixx>
            <ixy>0.000</ixy>
            <ixz>0.000</ixz>
            <iyy>0.016145833</iyy>
            <iyz>0.000</iyz>
            <izz>0.028125</izz>
          </inertia>
          <mass>10.0</mass>
        </inertial>

        <collision name="collision">
          <geometry>
            <cylinder>
              <radius>.075</radius>
              <length>.05</length>
            </cylinder>
          </geometry>
        </collision>
        <visual name="visual">
          <geometry>
            <cylinder>
              <radius>.075</radius>
              <length>.05</length>
            </cylinder>
          </geometry>
        </visual>
      </link>

      <link name="right_front_wheel">
        <pose>0.15 -0.13 0.1 0 1.5707 1.5707</pose>

        <inertial>
          <inertia>
            <ixx>0.016145833</ixx>
            <ixy>0.000</ixy>
            <ixz>0.000</ixz>
            <iyy>0.016145833</iyy>
            <iyz>0.000</iyz>
            <izz>0.028125</izz>
          </inertia>
          <mass>10.0</mass>
        </inertial>

        <collision name="collision">
          <geometry>
            <cylinder>
              <radius>.075</radius>
              <length>.05</length>
            </cylinder>
          </geometry>
        </collision>
        <visual name="visual">
          <geometry>
            <cylinder>
              <radius>.075</radius>
              <length>.05</length>
            </cylinder>
          </geometry>
        </visual>
      </link>

      <link name="left_rear_wheel">
        <pose>-0.15 0.13 0.1 0 1.5707 1.5707</pose>

        <inertial>
          <inertia>
            <ixx>0.016145833</ixx>
            <ixy>0.000</ixy>
            <ixz>0.000</ixz>
            <iyy>0.016145833</iyy>
            <iyz>0.000</iyz>
            <izz>0.028125</izz>
          </inertia>
          <mass>10.0</mass>
        </inertial>

        <collision name="collision">
          <geometry>
            <cylinder>
              <radius>.075</radius>
              <length>.05</length>
            </cylinder>
          </geometry>
        </collision>
        <visual name="visual">
          <geometry>
            <cylinder>
              <radius>.075</radius>
              <length>.05</length>
            </cylinder>
          </geometry>
        </visual>
      </link>

      <link name="right_rear_wheel">
        <pose>-0.15 -0.13 0.1 0 1.5707 1.5707</pose>

        <inertial>
          <inertia>
            <ixx>0.016145833</ixx>
            <ixy>0.000</ixy>
            <ixz>0.000</ixz>
            <iyy>0.016145833</iyy>
            <iyz>0.000</iyz>
            <izz>0.028125</izz>
          </inertia>
          <mass>10.0</mass>
        </inertial>
        
        <collision name="collision">
          <geometry>
            <cylinder>
              <radius>.075</radius>
              <length>.05</length>
            </cylinder>
          </geometry>
        </collision>
        <visual name="visual">
          <geometry>
            <cylinder>
              <radius>.075</radius>
              <length>.05</length>
            </cylinder>
          </geometry>
        </visual>
      </link>

      <link name="lidar_link">
        <inertial>
          <mass>0.1</mass>
        </inertial>
        <pose>0.15 0 0.175 0 0 0</pose>

        <visual name="visual">
          <geometry>
            <mesh>
              <uri>model://hokuyo/meshes/hokuyo.dae</uri>
            </mesh>
          </geometry>
        </visual>

        <collision name="collision-base">
          <pose>0 0 -0.0145 0 0 0</pose>
          <geometry>
            <box>
              <size>0.05 0.05 0.041</size>
            </box>
          </geometry>
        </collision>

        <collision name="collision-top">
          <pose>0 0 0.0205 0 0 0</pose>
          <geometry>
            <cylinder>
              <radius>0.021</radius>
              <length>0.029</length>
            </cylinder>
          </geometry>
        </collision>

        <sensor name="laser" type="ray">
          <pose>0.01 0 0.0175 0 -0 0</pose>

          <ray>
            <scan>
              <horizontal>
                <samples>360</samples>
                <resolution>1.00000</resolution>
                <min_angle>0.000000</min_angle>
                <max_angle>6.280000</max_angle>
              </horizontal>
            </scan>
            <range>
              <min>0.120000</min>
              <max>3.5</max>
              <resolution>0.015000</resolution>
            </range>
            <noise>
              <type>gaussian</type>
              <mean>0.0</mean>
              <stddev>0.01</stddev>
            </noise>
          </ray>
          <always_on>true</always_on>
          <update_rate>5</update_rate>
          <visualize>true</visualize>

          <plugin name='laser' filename='libgazebo_ros_ray_sensor.so'>
            <ros>
              <namespace>/osiris_exo</namespace>
              <remapping>~/out:=scan</remapping>
            </ros>
            <output_type>sensor_msgs/LaserScan</output_type>
            <frame_name>lidar_link</frame_name>
          </plugin>
        </sensor>

      </link>

      <joint name="base_link_joint" type="fixed">
        <pose>0 0 0.075 0 0 0</pose>
        <parent>base_footprint</parent>
        <child>base_link</child>
      </joint>

      <joint type="revolute" name="left_rear_wheel_joint">
        <pose>0 0 -0.03 0 0 0</pose>
        <child>left_rear_wheel</child>
        <parent>base_link</parent>
        <axis>
          <xyz>0 1 0</xyz>
        </axis>
      </joint>
      
      <joint type="revolute" name="right_rear_wheel_joint">
        <pose>0 0 0.03 0 0 0</pose>
        <child>right_rear_wheel</child>
        <parent>base_link</parent>
        <axis>
          <xyz>0 1 0</xyz>
        </axis>
      </joint>

      <joint type="revolute" name="left_front_wheel_joint">
        <pose>0 0 -0.03 0 0 0</pose>
        <child>left_front_wheel</child>
        <parent>base_link</parent>
        <axis>
          <xyz>0 1 0</xyz>
        </axis>
      </joint>
      
      <joint type="revolute" name="right_front_wheel_joint">
        <pose>0 0 0.03 0 0 0</pose>
        <child>right_front_wheel</child>
        <parent>base_link</parent>
        <axis>
          <xyz>0 1 0</xyz>
        </axis>
      </joint>

      <joint type="fixed" name="lidar_joint">
        <child>lidar_link</child>
        <parent>base_link</parent>
      </joint>
    

      <plugin name='diff_drive' filename='libgazebo_ros_diff_drive.so'>
         <ros>
           <namespace>/osiris_exo</namespace>
           <remapping>cmd_vel:=cmd_vel</remapping>
           <remapping>odom:=odom</remapping>
         </ros>

         <left_joint>left_rear_wheel_joint</left_joint>
         <right_joint>right_rear_wheel_joint</right_joint>

         <wheel_separation>0.26</wheel_separation>
         <wheel_diameter>0.2</wheel_diameter>

         <max_wheel_torque>20</max_wheel_torque>
         <max_wheel_acceleration>1.0</max_wheel_acceleration>

         <publish_odom>true</publish_odom>
         <publish_odom_tf>true</publish_odom_tf>
         <publish_wheel_tf>false</publish_wheel_tf>

         <odometry_frame>odom</odometry_frame>
        <robot_base_frame>base_footprint</robot_base_frame>
       </plugin>  

      <plugin name="simple_robot_joint_state" filename="libgazebo_ros_joint_state_publisher.so">
        <ros>
          <remapping>~/out:=joint_states</remapping>
        </ros>
        <update_rate>30</update_rate>
        <joint_name>right_rear_wheel_joint</joint_name>
        <joint_name>left_rear_wheel_joint</joint_name>
        <joint_name>right_front_wheel_joint</joint_name>
        <joint_name>left_front_wheel_joint</joint_name>
      </plugin>   

     

  </model>
</sdf>
